[{"body":"\nThis document addresses a common issue encountered when using Next.js API routes: the `UnhandledPromiseRejectionWarning`. This warning, while not immediately crashing your application, indicates a potential problem that could lead to instability or unexpected behavior.  It often arises when a promise within an API route is rejected without proper error handling.\n\n**Description of the Error:**\n\nThe `UnhandledPromiseRejectionWarning` appears in your console (usually during development) when a promise in your API route fails to be handled using `.catch()`. This can happen due to network errors, database errors, or any other unexpected failure within asynchronous operations.  Ignoring these warnings is not recommended as they can mask underlying issues and might lead to silent failures in production.\n\n**Example Scenario:**  Imagine an API route fetching data from an external API. If that external API is unavailable, the promise will reject. Without a `.catch()` block, the rejection goes unhandled, leading to the warning.\n\n\n**Code demonstrating the problem:**\n\n```javascript\n// pages/api/data.js\nexport default async function handler(req, res) {\n  try {\n    const response = await fetch('https://some-unreliable-api.com/data');\n    const data = await response.json();\n    res.status(200).json(data);\n  } catch (error) {\n    console.error(\"Error fetching data:\", error); //This will log the error, but the promise is still unhandled\n    res.status(500).json({ error: 'Failed to fetch data' });\n  }\n}\n```\n\n**Step-by-Step Code Fix:**\n\nThe solution is simple: ensure every promise within your API route is handled with a `.catch()` block. This allows you to gracefully handle errors, preventing the `UnhandledPromiseRejectionWarning`.\n\n```javascript\n// pages/api/data.js (Fixed)\nexport default async function handler(req, res) {\n  try {\n    const response = await fetch('https://some-unreliable-api.com/data')\n    .catch(error => {\n      console.error(\"Error fetching data:\", error);\n      throw new Error('Failed to fetch data from external API'); //Re-throwing allows the outer catch to handle it uniformly.\n    });\n\n    const data = await response.json();\n    res.status(200).json(data);\n  } catch (error) {\n    console.error(\"API Route Error:\", error);\n    res.status(500).json({ error: 'Failed to fetch data' });\n  }\n}\n```\n\n\n**Explanation:**\n\nThe improved code now includes a `.catch()` block within the `fetch` call itself. This ensures that if the `fetch` operation fails, the `catch` block is executed, logging the error, and re-throwing a more descriptive error to be caught by the outer `try...catch`. This allows you to handle errors uniformly without letting the unhandled promise warning slip through. The outer `try...catch` block provides a safety net for other potential errors that might occur within the API route.\n\n**External References:**\n\n* [Next.js API Routes Documentation](https://nextjs.org/docs/api-routes/introduction)\n* [Understanding Promises in JavaScript](https://developer.mozilla.org/en-US/docs/Web/JavaScript/Reference/Statements/async_function)\n* [Handling Errors in JavaScript](https://developer.mozilla.org/en-US/docs/Web/JavaScript/Guide/Control_flow_and_error_handling)\n\n\n**Conclusion:**\n\nProperly handling promises in your Next.js API routes is crucial for building robust and reliable applications.  By consistently using `.catch()` blocks, you can prevent `UnhandledPromiseRejectionWarning` and gracefully handle errors, improving the user experience and overall stability of your application.\n\nCopyrights (c) OpenRockets Open-source Network. Free to use, copy, share, edit or publish.\n","number":1108,"title":"Next.js Middleware: Handling `UnhandledPromiseRejectionWarning` in API Routes"}]
