[{"body":"\nThis document addresses a common error encountered when using Next.js Middleware with the `next/server` API:  Unexpected behavior or errors when using `Redirect()` within asynchronous operations or when improperly handling exceptions.\n\n**Description of the Error:**\n\nWhen using `next/server`'s `Redirect()` function within Middleware, developers frequently encounter issues stemming from asynchronous operations or unhandled exceptions. For example,  a `Redirect()` called inside a `try...catch` block might not function as expected if the `catch` block doesn't properly handle the error, leading to a silent failure or an incorrect redirection.  Another common issue is making a `Redirect()` call within a `Promise` or `async/await` function where error handling is overlooked.  This can result in a blank page, a 500 Internal Server Error, or a completely unexpected redirect.\n\n**Code (Illustrating the Problem & Solution):**\n\n**Problem Code (Incorrect Handling):**\n\n```javascript\n// pages/api/middleware.js\nimport { NextResponse } from 'next/server'\n\nexport function middleware(req) {\n  return new Promise(async (resolve) => {\n    try {\n      const response = await fetch('https://api.example.com/data'); // Simulate async operation\n      if (!response.ok) {\n        // INCORRECT:  This throws an error, but the Middleware doesn't handle it properly.\n        throw new Error(`Failed to fetch data: ${response.status}`);\n      }\n\n      const data = await response.json();\n      if (data.redirect) {\n          return resolve(NextResponse.redirect(data.redirectUrl)); //This might not resolve correctly if an error occurs above\n      }\n      return resolve(NextResponse.next());\n    } catch (error) {\n      console.error(\"Error in middleware:\", error); //Logging the error isn't sufficient to handle it.\n    }\n  });\n}\n\nexport const config = {\n  matcher: '/about/:path*'\n};\n```\n\n**Solution Code (Corrected Handling):**\n\n\n```javascript\n// pages/api/middleware.js\nimport { NextResponse } from 'next/server'\n\nexport function middleware(req) {\n  return new Promise(async (resolve, reject) => { // Use reject to handle errors\n    try {\n      const response = await fetch('https://api.example.com/data');\n      if (!response.ok) {\n        //Correct error handling: reject the promise\n        return reject(new Error(`Failed to fetch data: ${response.status}`)); \n      }\n\n      const data = await response.json();\n      if (data.redirect) {\n        resolve(NextResponse.redirect(data.redirectUrl));\n      } else {\n        resolve(NextResponse.next());\n      }\n    } catch (error) {\n      reject(error); // Pass error to the promise reject handler.\n    }\n  })\n  .catch(error => { //handle rejected promises\n    console.error(\"Error in middleware:\", error);\n    return NextResponse.rewrite(new URL('/error', req.url)); // Redirect to error page if needed.\n  });\n}\n\nexport const config = {\n  matcher: '/about/:path*'\n};\n\n```\n\n**Explanation:**\n\nThe problem code failed to properly handle errors in the asynchronous operation and within the `try...catch` block.  The improved code uses `Promise.reject()` to handle errors properly within the asynchronous operation and catch them via `.catch()` after the `Promise`. This ensures that a proper response (in this case, a redirect to an error page) is returned, preventing unexpected behavior.  Simply logging the error in the `catch` block isn't sufficient to prevent the middleware from failing silently.\n\n**External References:**\n\n* [Next.js Middleware Documentation](https://nextjs.org/docs/app/building-your-application/routing/middleware)\n* [Next.js `next/server` API](https://nextjs.org/docs/app/api-routes/introduction)\n* [Handling Promises and Async/Await](https://developer.mozilla.org/en-US/docs/Web/JavaScript/Reference/Statements/async_function)\n\n\nCopyrights (c) OpenRockets Open-source Network. Free to use, copy, share, edit or publish.\n","number":904,"title":"Next.js Middleware: Handling `Redirect()` Errors in `next/server`"}]
